#######
# Compiled from data/drh/functions/load.mcscript
# to .//drh/data/drh/functions/build_room.mcfunction
#
# Generated by Minecraft Script for 1.16
######
# this file is generated based on a function specified in.//drh/data/drh/functions/load.mcscript
say  DEBUG build_room
fill ~-4 ~ ~-4 ~4 ~5 ~4 minecraft:air
fill ~-4 ~-1 ~-4 ~4 ~-1 ~4 minecraft:glowstone
fill ~-3 ~-1 ~-4 ~3 ~-1 ~4 minecraft:glass
fill ~-4 ~-1 ~-3 ~4 ~-1 ~3 minecraft:glass
fill ~-3 ~-1 ~-3 ~3 ~5 ~3 minecraft:glass hollow
fill ~-3 ~-1 ~-3 ~3 ~-1 ~3 minecraft:polished_diorite
fill ~-3 ~ ~-3 ~3 ~ ~3 minecraft:polished_andesite replace glass
fill ~-3 ~4 ~-3 ~3 ~4 ~3 minecraft:polished_andesite replace glass
fill ~ ~-1 ~ ~ ~-1 ~ minecraft:glowstone
fill ~-3 ~0 ~-3 ~-3 ~4 ~-3 minecraft:cobblestone_wall
fill ~-3 ~0 ~3 ~-3 ~4 ~3 minecraft:cobblestone_wall
fill ~3 ~0 ~-3 ~3 ~4 ~-3 minecraft:cobblestone_wall
fill ~3 ~0 ~3 ~3 ~4 ~3 minecraft:cobblestone_wall
fill ~-1 ~-1 ~ ~-1 ~-1 ~2 minecraft:cobblestone
fill ~-1 ~2 ~ ~-1 ~4 ~2 minecraft:cobblestone_wall
fill ~-1 ~ ~ ~-1 ~ ~2 minecraft:oak_door[facing=west,half=lower]
fill ~-1 ~1 ~ ~-1 ~1 ~2 minecraft:oak_door[facing=west,half=upper]
fill ~3 ~ ~2 ~3 ~1 ~2 minecraft:air
fill ~2 ~ ~3 ~2 ~1 ~3 minecraft:air
fill ~2 ~2 ~2 ~2 ~2 ~2 minecraft:polished_diorite
fill ~2 ~1 ~2 ~2 ~1 ~2 minecraft:oak_button[face=ceiling]
fill ~2 ~ ~1 ~2 ~ ~1 minecraft:iron_door[facing=north,half=lower,hinge=right]
fill ~2 ~1 ~1 ~2 ~1 ~1 minecraft:iron_door[facing=north,half=upper,hinge=right]
fill ~1 ~ ~2 ~1 ~ ~2 minecraft:iron_door[facing=west,half=lower]
fill ~1 ~1 ~2 ~1 ~1 ~2 minecraft:iron_door[facing=west,half=upper]
fill ~1 ~ ~1 ~1 ~ ~1 minecraft:stone_pressure_plate
fill ~2 ~ ~ ~2 ~1 ~ minecraft:iron_bars
fill ~ ~ ~2 ~ ~1 ~2 minecraft:iron_bars
fill ~1 ~-1 ~-2 ~1 ~4 ~-2 minecraft:glass
fill ~2 ~-1 ~-1 ~2 ~4 ~-1 minecraft:glass
fill ~2 ~2 ~-1 ~2 ~2 ~-1 minecraft:dropper[facing=north]